2020-09-01 13:39:56,740 ERROR: Exception on /auth/login [GET] [in /Users/elaineyang/Desktop/web_practice/microblog_flask/venv/lib/python3.8/site-packages/flask/app.py:1891]
Traceback (most recent call last):
  File "/Users/elaineyang/Desktop/web_practice/microblog_flask/venv/lib/python3.8/site-packages/flask/app.py", line 2447, in wsgi_app
    response = self.full_dispatch_request()
  File "/Users/elaineyang/Desktop/web_practice/microblog_flask/venv/lib/python3.8/site-packages/flask/app.py", line 1952, in full_dispatch_request
    rv = self.handle_user_exception(e)
  File "/Users/elaineyang/Desktop/web_practice/microblog_flask/venv/lib/python3.8/site-packages/flask/app.py", line 1821, in handle_user_exception
    reraise(exc_type, exc_value, tb)
  File "/Users/elaineyang/Desktop/web_practice/microblog_flask/venv/lib/python3.8/site-packages/flask/_compat.py", line 39, in reraise
    raise value
  File "/Users/elaineyang/Desktop/web_practice/microblog_flask/venv/lib/python3.8/site-packages/flask/app.py", line 1950, in full_dispatch_request
    rv = self.dispatch_request()
  File "/Users/elaineyang/Desktop/web_practice/microblog_flask/venv/lib/python3.8/site-packages/flask/app.py", line 1936, in dispatch_request
    return self.view_functions[rule.endpoint](**req.view_args)
  File "/Users/elaineyang/Desktop/lamb_project/microblog_flask_OAuth2/app/auth/routes.py", line 36, in login
    return render_template('auth/login.html', title=_('Sign In'), form=form)
  File "/Users/elaineyang/Desktop/web_practice/microblog_flask/venv/lib/python3.8/site-packages/flask/templating.py", line 137, in render_template
    return _render(
  File "/Users/elaineyang/Desktop/web_practice/microblog_flask/venv/lib/python3.8/site-packages/flask/templating.py", line 120, in _render
    rv = template.render(context)
  File "/Users/elaineyang/Desktop/web_practice/microblog_flask/venv/lib/python3.8/site-packages/jinja2/environment.py", line 1090, in render
    self.environment.handle_exception()
  File "/Users/elaineyang/Desktop/web_practice/microblog_flask/venv/lib/python3.8/site-packages/jinja2/environment.py", line 832, in handle_exception
    reraise(*rewrite_traceback_stack(source=source))
  File "/Users/elaineyang/Desktop/web_practice/microblog_flask/venv/lib/python3.8/site-packages/jinja2/_compat.py", line 28, in reraise
    raise value.with_traceback(tb)
  File "/Users/elaineyang/Desktop/lamb_project/microblog_flask_OAuth2/app/templates/auth/login.html", line 1, in top-level template code
    {% extends 'base.html' %}
  File "/Users/elaineyang/Desktop/web_practice/microblog_flask/venv/lib/python3.8/site-packages/jinja2/environment.py", line 832, in handle_exception
    reraise(*rewrite_traceback_stack(source=source))
  File "/Users/elaineyang/Desktop/web_practice/microblog_flask/venv/lib/python3.8/site-packages/jinja2/_compat.py", line 28, in reraise
    raise value.with_traceback(tb)
  File "/Users/elaineyang/Desktop/lamb_project/microblog_flask_OAuth2/app/templates/base.html", line 20, in template
    <!--{% block title %}
jinja2.exceptions.TemplateAssertionError: block 'title' defined twice
2020-09-01 13:41:08,736 INFO: Microblog startup [in /Users/elaineyang/Desktop/lamb_project/microblog_flask_OAuth2/app/__init__.py:92]
2020-09-01 13:41:11,725 ERROR: Exception on /auth/login [GET] [in /Users/elaineyang/Desktop/web_practice/microblog_flask/venv/lib/python3.8/site-packages/flask/app.py:1891]
Traceback (most recent call last):
  File "/Users/elaineyang/Desktop/web_practice/microblog_flask/venv/lib/python3.8/site-packages/flask/app.py", line 2447, in wsgi_app
    response = self.full_dispatch_request()
  File "/Users/elaineyang/Desktop/web_practice/microblog_flask/venv/lib/python3.8/site-packages/flask/app.py", line 1952, in full_dispatch_request
    rv = self.handle_user_exception(e)
  File "/Users/elaineyang/Desktop/web_practice/microblog_flask/venv/lib/python3.8/site-packages/flask/app.py", line 1821, in handle_user_exception
    reraise(exc_type, exc_value, tb)
  File "/Users/elaineyang/Desktop/web_practice/microblog_flask/venv/lib/python3.8/site-packages/flask/_compat.py", line 39, in reraise
    raise value
  File "/Users/elaineyang/Desktop/web_practice/microblog_flask/venv/lib/python3.8/site-packages/flask/app.py", line 1950, in full_dispatch_request
    rv = self.dispatch_request()
  File "/Users/elaineyang/Desktop/web_practice/microblog_flask/venv/lib/python3.8/site-packages/flask/app.py", line 1936, in dispatch_request
    return self.view_functions[rule.endpoint](**req.view_args)
  File "/Users/elaineyang/Desktop/lamb_project/microblog_flask_OAuth2/app/auth/routes.py", line 36, in login
    return render_template('auth/login.html', title=_('Sign In'), form=form)
  File "/Users/elaineyang/Desktop/web_practice/microblog_flask/venv/lib/python3.8/site-packages/flask/templating.py", line 137, in render_template
    return _render(
  File "/Users/elaineyang/Desktop/web_practice/microblog_flask/venv/lib/python3.8/site-packages/flask/templating.py", line 120, in _render
    rv = template.render(context)
  File "/Users/elaineyang/Desktop/web_practice/microblog_flask/venv/lib/python3.8/site-packages/jinja2/environment.py", line 1090, in render
    self.environment.handle_exception()
  File "/Users/elaineyang/Desktop/web_practice/microblog_flask/venv/lib/python3.8/site-packages/jinja2/environment.py", line 832, in handle_exception
    reraise(*rewrite_traceback_stack(source=source))
  File "/Users/elaineyang/Desktop/web_practice/microblog_flask/venv/lib/python3.8/site-packages/jinja2/_compat.py", line 28, in reraise
    raise value.with_traceback(tb)
  File "/Users/elaineyang/Desktop/lamb_project/microblog_flask_OAuth2/app/templates/auth/login.html", line 1, in top-level template code
    {% extends 'base.html' %}
  File "/Users/elaineyang/Desktop/web_practice/microblog_flask/venv/lib/python3.8/site-packages/jinja2/environment.py", line 832, in handle_exception
    reraise(*rewrite_traceback_stack(source=source))
  File "/Users/elaineyang/Desktop/web_practice/microblog_flask/venv/lib/python3.8/site-packages/jinja2/_compat.py", line 28, in reraise
    raise value.with_traceback(tb)
  File "/Users/elaineyang/Desktop/lamb_project/microblog_flask_OAuth2/app/templates/base.html", line 22, in template
    <!--{% block title %}
jinja2.exceptions.TemplateAssertionError: block 'title' defined twice
2020-09-01 13:43:23,846 INFO: Microblog startup [in /Users/elaineyang/Desktop/lamb_project/microblog_flask_OAuth2/app/__init__.py:92]
