2020-09-03 14:58:53,381 ERROR: Exception on /auth/login [GET] [in /Users/elaineyang/Desktop/web_practice/microblog_flask/venv/lib/python3.8/site-packages/flask/app.py:1891]
Traceback (most recent call last):
  File "/Users/elaineyang/Desktop/web_practice/microblog_flask/venv/lib/python3.8/site-packages/flask/app.py", line 2447, in wsgi_app
    response = self.full_dispatch_request()
  File "/Users/elaineyang/Desktop/web_practice/microblog_flask/venv/lib/python3.8/site-packages/flask/app.py", line 1952, in full_dispatch_request
    rv = self.handle_user_exception(e)
  File "/Users/elaineyang/Desktop/web_practice/microblog_flask/venv/lib/python3.8/site-packages/flask/app.py", line 1821, in handle_user_exception
    reraise(exc_type, exc_value, tb)
  File "/Users/elaineyang/Desktop/web_practice/microblog_flask/venv/lib/python3.8/site-packages/flask/_compat.py", line 39, in reraise
    raise value
  File "/Users/elaineyang/Desktop/web_practice/microblog_flask/venv/lib/python3.8/site-packages/flask/app.py", line 1948, in full_dispatch_request
    rv = self.preprocess_request()
  File "/Users/elaineyang/Desktop/web_practice/microblog_flask/venv/lib/python3.8/site-packages/flask/app.py", line 2242, in preprocess_request
    rv = func()
  File "/Users/elaineyang/Desktop/lamb_project/microblog_flask_OAuth2/app/main/routes.py", line 16, in before_request
    if current_user.is_authenticated:
  File "/Users/elaineyang/Desktop/web_practice/microblog_flask/venv/lib/python3.8/site-packages/werkzeug/local.py", line 347, in __getattr__
    return getattr(self._get_current_object(), name)
  File "/Users/elaineyang/Desktop/web_practice/microblog_flask/venv/lib/python3.8/site-packages/werkzeug/local.py", line 306, in _get_current_object
    return self.__local()
  File "/Users/elaineyang/Desktop/web_practice/microblog_flask/venv/lib/python3.8/site-packages/flask_login/utils.py", line 26, in <lambda>
    current_user = LocalProxy(lambda: _get_user())
  File "/Users/elaineyang/Desktop/web_practice/microblog_flask/venv/lib/python3.8/site-packages/flask_login/utils.py", line 346, in _get_user
    current_app.login_manager._load_user()
  File "/Users/elaineyang/Desktop/web_practice/microblog_flask/venv/lib/python3.8/site-packages/flask_login/login_manager.py", line 318, in _load_user
    user = self._user_callback(user_id)
  File "/Users/elaineyang/Desktop/lamb_project/microblog_flask_OAuth2/app/models.py", line 138, in load_user
    print(User.query.get())
TypeError: get() missing 1 required positional argument: 'ident'
2020-09-03 14:58:54,690 ERROR: Exception on /auth/callback/facebook [GET] [in /Users/elaineyang/Desktop/web_practice/microblog_flask/venv/lib/python3.8/site-packages/flask/app.py:1891]
Traceback (most recent call last):
  File "/Users/elaineyang/Desktop/web_practice/microblog_flask/venv/lib/python3.8/site-packages/flask/app.py", line 2447, in wsgi_app
    response = self.full_dispatch_request()
  File "/Users/elaineyang/Desktop/web_practice/microblog_flask/venv/lib/python3.8/site-packages/flask/app.py", line 1952, in full_dispatch_request
    rv = self.handle_user_exception(e)
  File "/Users/elaineyang/Desktop/web_practice/microblog_flask/venv/lib/python3.8/site-packages/flask/app.py", line 1821, in handle_user_exception
    reraise(exc_type, exc_value, tb)
  File "/Users/elaineyang/Desktop/web_practice/microblog_flask/venv/lib/python3.8/site-packages/flask/_compat.py", line 39, in reraise
    raise value
  File "/Users/elaineyang/Desktop/web_practice/microblog_flask/venv/lib/python3.8/site-packages/flask/app.py", line 1948, in full_dispatch_request
    rv = self.preprocess_request()
  File "/Users/elaineyang/Desktop/web_practice/microblog_flask/venv/lib/python3.8/site-packages/flask/app.py", line 2242, in preprocess_request
    rv = func()
  File "/Users/elaineyang/Desktop/lamb_project/microblog_flask_OAuth2/app/main/routes.py", line 16, in before_request
    if current_user.is_authenticated:
  File "/Users/elaineyang/Desktop/web_practice/microblog_flask/venv/lib/python3.8/site-packages/werkzeug/local.py", line 347, in __getattr__
    return getattr(self._get_current_object(), name)
  File "/Users/elaineyang/Desktop/web_practice/microblog_flask/venv/lib/python3.8/site-packages/werkzeug/local.py", line 306, in _get_current_object
    return self.__local()
  File "/Users/elaineyang/Desktop/web_practice/microblog_flask/venv/lib/python3.8/site-packages/flask_login/utils.py", line 26, in <lambda>
    current_user = LocalProxy(lambda: _get_user())
  File "/Users/elaineyang/Desktop/web_practice/microblog_flask/venv/lib/python3.8/site-packages/flask_login/utils.py", line 346, in _get_user
    current_app.login_manager._load_user()
  File "/Users/elaineyang/Desktop/web_practice/microblog_flask/venv/lib/python3.8/site-packages/flask_login/login_manager.py", line 318, in _load_user
    user = self._user_callback(user_id)
  File "/Users/elaineyang/Desktop/lamb_project/microblog_flask_OAuth2/app/models.py", line 138, in load_user
    print(User.query.get())
TypeError: get() missing 1 required positional argument: 'ident'
2020-09-03 14:58:56,336 ERROR: Exception on /auth/callback/facebook [GET] [in /Users/elaineyang/Desktop/web_practice/microblog_flask/venv/lib/python3.8/site-packages/flask/app.py:1891]
Traceback (most recent call last):
  File "/Users/elaineyang/Desktop/web_practice/microblog_flask/venv/lib/python3.8/site-packages/flask/app.py", line 2447, in wsgi_app
    response = self.full_dispatch_request()
  File "/Users/elaineyang/Desktop/web_practice/microblog_flask/venv/lib/python3.8/site-packages/flask/app.py", line 1952, in full_dispatch_request
    rv = self.handle_user_exception(e)
  File "/Users/elaineyang/Desktop/web_practice/microblog_flask/venv/lib/python3.8/site-packages/flask/app.py", line 1821, in handle_user_exception
    reraise(exc_type, exc_value, tb)
  File "/Users/elaineyang/Desktop/web_practice/microblog_flask/venv/lib/python3.8/site-packages/flask/_compat.py", line 39, in reraise
    raise value
  File "/Users/elaineyang/Desktop/web_practice/microblog_flask/venv/lib/python3.8/site-packages/flask/app.py", line 1948, in full_dispatch_request
    rv = self.preprocess_request()
  File "/Users/elaineyang/Desktop/web_practice/microblog_flask/venv/lib/python3.8/site-packages/flask/app.py", line 2242, in preprocess_request
    rv = func()
  File "/Users/elaineyang/Desktop/lamb_project/microblog_flask_OAuth2/app/main/routes.py", line 16, in before_request
    if current_user.is_authenticated:
  File "/Users/elaineyang/Desktop/web_practice/microblog_flask/venv/lib/python3.8/site-packages/werkzeug/local.py", line 347, in __getattr__
    return getattr(self._get_current_object(), name)
  File "/Users/elaineyang/Desktop/web_practice/microblog_flask/venv/lib/python3.8/site-packages/werkzeug/local.py", line 306, in _get_current_object
    return self.__local()
  File "/Users/elaineyang/Desktop/web_practice/microblog_flask/venv/lib/python3.8/site-packages/flask_login/utils.py", line 26, in <lambda>
    current_user = LocalProxy(lambda: _get_user())
  File "/Users/elaineyang/Desktop/web_practice/microblog_flask/venv/lib/python3.8/site-packages/flask_login/utils.py", line 346, in _get_user
    current_app.login_manager._load_user()
  File "/Users/elaineyang/Desktop/web_practice/microblog_flask/venv/lib/python3.8/site-packages/flask_login/login_manager.py", line 318, in _load_user
    user = self._user_callback(user_id)
  File "/Users/elaineyang/Desktop/lamb_project/microblog_flask_OAuth2/app/models.py", line 138, in load_user
    print(User.query.get())
TypeError: get() missing 1 required positional argument: 'ident'
2020-09-03 14:59:35,747 INFO: Microblog startup [in /Users/elaineyang/Desktop/lamb_project/microblog_flask_OAuth2/app/__init__.py:92]
