2020-09-01 11:46:16,816 ERROR: Exception on /auth/authorize/google [GET] [in /Users/elaineyang/Desktop/web_practice/microblog_flask/venv/lib/python3.8/site-packages/flask/app.py:1891]
Traceback (most recent call last):
  File "/Users/elaineyang/Desktop/web_practice/microblog_flask/venv/lib/python3.8/site-packages/flask/app.py", line 2447, in wsgi_app
    response = self.full_dispatch_request()
  File "/Users/elaineyang/Desktop/web_practice/microblog_flask/venv/lib/python3.8/site-packages/flask/app.py", line 1952, in full_dispatch_request
    rv = self.handle_user_exception(e)
  File "/Users/elaineyang/Desktop/web_practice/microblog_flask/venv/lib/python3.8/site-packages/flask/app.py", line 1821, in handle_user_exception
    reraise(exc_type, exc_value, tb)
  File "/Users/elaineyang/Desktop/web_practice/microblog_flask/venv/lib/python3.8/site-packages/flask/_compat.py", line 39, in reraise
    raise value
  File "/Users/elaineyang/Desktop/web_practice/microblog_flask/venv/lib/python3.8/site-packages/flask/app.py", line 1950, in full_dispatch_request
    rv = self.dispatch_request()
  File "/Users/elaineyang/Desktop/web_practice/microblog_flask/venv/lib/python3.8/site-packages/flask/app.py", line 1936, in dispatch_request
    return self.view_functions[rule.endpoint](**req.view_args)
  File "/Users/elaineyang/Desktop/lamb_project/microblog_flask_OAuth2/app/auth/routes.py", line 98, in oauth_authorize
    return oauth.authorize()
  File "/Users/elaineyang/Desktop/lamb_project/microblog_flask_OAuth2/app/auth/oauth.py", line 62, in authorize
    redirect_uri=self.get_callback_url())
  File "/Users/elaineyang/Desktop/lamb_project/microblog_flask_OAuth2/app/auth/oauth.py", line 32, in get_callback_url
    return url_for('http://localhost:5000/oauth2callback', provider=self.provider_name,
  File "/Users/elaineyang/Desktop/web_practice/microblog_flask/venv/lib/python3.8/site-packages/flask/helpers.py", line 370, in url_for
    return appctx.app.handle_url_build_error(error, endpoint, values)
  File "/Users/elaineyang/Desktop/web_practice/microblog_flask/venv/lib/python3.8/site-packages/flask/app.py", line 2216, in handle_url_build_error
    reraise(exc_type, exc_value, tb)
  File "/Users/elaineyang/Desktop/web_practice/microblog_flask/venv/lib/python3.8/site-packages/flask/_compat.py", line 39, in reraise
    raise value
  File "/Users/elaineyang/Desktop/web_practice/microblog_flask/venv/lib/python3.8/site-packages/flask/helpers.py", line 357, in url_for
    rv = url_adapter.build(
  File "/Users/elaineyang/Desktop/web_practice/microblog_flask/venv/lib/python3.8/site-packages/werkzeug/routing.py", line 2179, in build
    raise BuildError(endpoint, values, method, self)
werkzeug.routing.BuildError: Could not build url for endpoint 'http://localhost:5000/oauth2callback' with values ['provider']. Did you mean 'auth.oauth_callback' instead?
2020-09-01 11:49:40,300 INFO: Microblog startup [in /Users/elaineyang/Desktop/lamb_project/microblog_flask_OAuth2/app/__init__.py:92]
2020-09-01 13:10:33,996 INFO: Microblog startup [in /Users/elaineyang/Desktop/lamb_project/microblog_flask_OAuth2/app/__init__.py:92]
2020-09-01 13:12:34,620 INFO: Microblog startup [in /Users/elaineyang/Desktop/lamb_project/microblog_flask_OAuth2/app/__init__.py:92]
2020-09-01 13:12:52,110 INFO: Microblog startup [in /Users/elaineyang/Desktop/lamb_project/microblog_flask_OAuth2/app/__init__.py:92]
2020-09-01 13:13:27,335 INFO: Microblog startup [in /Users/elaineyang/Desktop/lamb_project/microblog_flask_OAuth2/app/__init__.py:92]
2020-09-01 13:14:14,712 INFO: Microblog startup [in /Users/elaineyang/Desktop/lamb_project/microblog_flask_OAuth2/app/__init__.py:92]
2020-09-01 13:14:50,226 INFO: Microblog startup [in /Users/elaineyang/Desktop/lamb_project/microblog_flask_OAuth2/app/__init__.py:92]
2020-09-01 13:38:27,355 INFO: Microblog startup [in /Users/elaineyang/Desktop/lamb_project/microblog_flask_OAuth2/app/__init__.py:92]
2020-09-01 13:38:30,967 ERROR: Exception on /auth/login [GET] [in /Users/elaineyang/Desktop/web_practice/microblog_flask/venv/lib/python3.8/site-packages/flask/app.py:1891]
Traceback (most recent call last):
  File "/Users/elaineyang/Desktop/web_practice/microblog_flask/venv/lib/python3.8/site-packages/flask/app.py", line 2447, in wsgi_app
    response = self.full_dispatch_request()
  File "/Users/elaineyang/Desktop/web_practice/microblog_flask/venv/lib/python3.8/site-packages/flask/app.py", line 1952, in full_dispatch_request
    rv = self.handle_user_exception(e)
  File "/Users/elaineyang/Desktop/web_practice/microblog_flask/venv/lib/python3.8/site-packages/flask/app.py", line 1821, in handle_user_exception
    reraise(exc_type, exc_value, tb)
  File "/Users/elaineyang/Desktop/web_practice/microblog_flask/venv/lib/python3.8/site-packages/flask/_compat.py", line 39, in reraise
    raise value
  File "/Users/elaineyang/Desktop/web_practice/microblog_flask/venv/lib/python3.8/site-packages/flask/app.py", line 1950, in full_dispatch_request
    rv = self.dispatch_request()
  File "/Users/elaineyang/Desktop/web_practice/microblog_flask/venv/lib/python3.8/site-packages/flask/app.py", line 1936, in dispatch_request
    return self.view_functions[rule.endpoint](**req.view_args)
  File "/Users/elaineyang/Desktop/lamb_project/microblog_flask_OAuth2/app/auth/routes.py", line 36, in login
    return render_template('auth/login.html', title=_('Sign In'), form=form)
  File "/Users/elaineyang/Desktop/web_practice/microblog_flask/venv/lib/python3.8/site-packages/flask/templating.py", line 137, in render_template
    return _render(
  File "/Users/elaineyang/Desktop/web_practice/microblog_flask/venv/lib/python3.8/site-packages/flask/templating.py", line 120, in _render
    rv = template.render(context)
  File "/Users/elaineyang/Desktop/web_practice/microblog_flask/venv/lib/python3.8/site-packages/jinja2/environment.py", line 1090, in render
    self.environment.handle_exception()
  File "/Users/elaineyang/Desktop/web_practice/microblog_flask/venv/lib/python3.8/site-packages/jinja2/environment.py", line 832, in handle_exception
    reraise(*rewrite_traceback_stack(source=source))
  File "/Users/elaineyang/Desktop/web_practice/microblog_flask/venv/lib/python3.8/site-packages/jinja2/_compat.py", line 28, in reraise
    raise value.with_traceback(tb)
  File "/Users/elaineyang/Desktop/lamb_project/microblog_flask_OAuth2/app/templates/auth/login.html", line 1, in top-level template code
    {% extends 'base.html' %}
  File "/Users/elaineyang/Desktop/web_practice/microblog_flask/venv/lib/python3.8/site-packages/jinja2/environment.py", line 832, in handle_exception
    reraise(*rewrite_traceback_stack(source=source))
  File "/Users/elaineyang/Desktop/web_practice/microblog_flask/venv/lib/python3.8/site-packages/jinja2/_compat.py", line 28, in reraise
    raise value.with_traceback(tb)
  File "/Users/elaineyang/Desktop/lamb_project/microblog_flask_OAuth2/app/templates/base.html", line 10, in template
    {% if title %}{{ title }} - Elaine's Microblog{% else %}{{ _('Welcome to Elaine's Microblog') }}{% endif %}
jinja2.exceptions.TemplateSyntaxError: expected token ',', got 's'
2020-09-01 13:39:55,292 INFO: Microblog startup [in /Users/elaineyang/Desktop/lamb_project/microblog_flask_OAuth2/app/__init__.py:92]
